Workbook

Sheet Sales
A1: country | B1: order_value_GBP | C1: cost | D1: date | E1: category | F1: customer_name | G1: sales_manager | H1: sales_rep | I1: device_type | J1: order_id | K1: profit | L1: Unique | M1: Order Size Bin | N1: Order Size Classification | O1: Bin Floor
A2: Sweden | B2: 17524.02 | C2: 14122.61 | D2: 43873 | E2: Books | F2: Goldner-Dibbert | G2: Maxie Marrow | H2: Madelon Bront | I2: Mobile | J2: 70-0511466 | K2: =Sales_Export_2019_2020__2[[#This Row],[order_value_GBP]]-Sales_Export_2019_2020__2[[#This Row],[ cost ]] -> 3401.41 | L2: =COUNTIF(Sales_Export_2019_2020__2[order_id],Sales_Export_2019_2020__2[[#This Row],[order_id]])>1 -> FALSE | M2: =TEXT(FLOOR(B2,5000),"£#,##0")&" - "&TEXT(FLOOR(B2,5000)+4999,"£#,##0") -> £15,000 - £19,999 | N2: {=_xlfn.IFS(Sales_Export_2019_2020__2[[#This Row],[order_value_GBP]]>Summary!$E$3+Summary!$I$4,"Large",Sales_Export_2019_2020__2[[#This Row],[order_value_GBP]]<Summary!$E$3-Summary!$I$4,"Small",AND(Sales_Export_2019_2020__2[[#This Row],[order_value_GBP]]<Summary!$E$3+Summary!$I$4,Sales_Export_2019_2020__2[[#This Row],[order_value_GBP]]>Summary!$E$3-Summary!$I$4),"Average")} -> Small | O2: =FLOOR(Sales_Export_2019_2020__2[[#This Row],[order_value_GBP]],5000) -> 15000
A3: Finland | B3: 116563.4 | C3: 92807.78 | D3: 43734 | E3: Games | F3: Hilll-Vandervort | G3: Hube Corey | H3: Wat Bowkley | I3: Mobile | J3: 28-6585323 | K3: =Sales_Export_2019_2020__2[[#This Row],[order_value_GBP]]-Sales_Export_2019_2020__2[[#This Row],[ cost ]] -> 23755.62 | L3: =COUNTIF(Sales_Export_2019_2020__2[order_id],Sales_Export_2019_2020__2[[#This Row],[order_id]])>1 -> FALSE | M3: =TEXT(FLOOR(B3,5000),"£#,##0")&" - "&TEXT(FLOOR(B3,5000)+4999,"£#,##0") -> £115,000 - £119,999 | N3: {=_xlfn.IFS(Sales_Export_2019_2020__2[[#This Row],[order_value_GBP]]>Summary!$E$3+Summary!$I$4,"Large",Sales_Export_2019_2020__2[[#This Row],[order_value_GBP]]<Summary!$E$3-Summary!$I$4,"Small",AND(Sales_Export_2019_2020__2[[#This Row],[order_value_GBP]]<Summary!$E$3+Summary!$I$4,Sales_Export_2019_2020__2[[#This Row],[order_value_GBP]]>Summary!$E$3-Summary!$I$4),"Average")} -> Average | O3: =FLOOR(Sales_Export_2019_2020__2[[#This Row],[order_value_GBP]],5000) -> 115000
A4: Portugal | B4: 296465.56 | C4: 257480.34 | D4: 43657 | E4: Clothing | F4: Larkin-Collier | G4: Celine Tumasian | H4: Smitty Culverhouse | I4: PC | J4: 58-7703341 | K4: =Sales_Export_2019_2020__2[[#This Row],[order_value_GBP]]-Sales_Export_2019_2020__2[[#This Row],[ cost ]] -> 38985.22 | L4: =COUNTIF(Sales_Export_2019_2020__2[order_id],Sales_Export_2019_2020__2[[#This Row],[order_id]])>1 -> FALSE | M4: =TEXT(FLOOR(B4,5000),"£#,##0")&" - "&TEXT(FLOOR(B4,5000)+4999,"£#,##0") -> £295,000 - £299,999 | N4: {=_xlfn.IFS(Sales_Export_2019_2020__2[[#This Row],[order_value_GBP]]>Summary!$E$3+Summary!$I$4,"Large",Sales_Export_2019_2020__2[[#This Row],[order_value_GBP]]<Summary!$E$3-Summary!$I$4,"Small",AND(Sales_Export_2019_2020__2[[#This Row],[order_value_GBP]]<Summary!$E$3+Summary!$I$4,Sales_Export_2019_2020__2[[#This Row],[order_value_GBP]]>Summary!$E$3-Summary!$I$4),"Average")} -> Large | O4: =FLOOR(Sales_Export_2019_2020__2[[#This Row],[order_value_GBP]],5000) -> 295000
A5: Portugal | B5: 74532.02 | C5: 59752.32 | D5: 43923 | E5: Beauty | F5: Hessel-Stiedemann | G5: Celine Tumasian | H5: Aurelie Wren | I5: PC | J5: 14-6700183 | K5: =Sales_Export_2019_2020__2[[#This Row],[order_value_GBP]]-Sales_Export_2019_2020__2[[#This Row],[ cost ]] -> 14779.7 | L5: =COUNTIF(Sales_Export_2019_2020__2[order_id],Sales_Export_2019_2020__2[[#This Row],[order_id]])>1 -> FALSE | M5: =TEXT(FLOOR(B5,5000),"£#,##0")&" - "&TEXT(FLOOR(B5,5000)+4999,"£#,##0") -> £70,000 - £74,999 | N5: {=_xlfn.IFS(Sales_Export_2019_2020__2[[#This Row],[order_value_GBP]]>Summary!$E$3+Summary!$I$4,"Large",Sales_Export_2019_2020__2[[#This Row],[order_value_GBP]]<Summary!$E$3-Summary!$I$4,"Small",AND(Sales_Export_2019_2020__2[[#This Row],[order_value_GBP]]<Summary!$E$3+Summary!$I$4,Sales_Export_2019_2020__2[[#This Row],[order_value_GBP]]>Summary!$E$3-Summary!$I$4),"Average")} -> Average | O5: =FLOOR(Sales_Export_2019_2020__2[[#This Row],[order_value_GBP]],5000) -> 70000
A6: Spain | B6: 178763.42 | C6: 146621.76 | D6: 43821 | E6: Games | F6: Johns and Sons | G6: Emalia Dinse | H6: Bertha Walbrook | I6: Tablet | J6: 15-8765160 | K6: =Sales_Export_2019_2020__2[[#This Row],[order_value_GBP]]-Sales_Export_2019_2020__2[[#This Row],[ cost ]] -> 32141.66 | L6: =COUNTIF(Sales_Export_2019_2020__2[order_id],Sales_Export_2019_2020__2[[#This Row],[order_id]])>1 -> FALSE | M6: =TEXT(FLOOR(B6,5000),"£#,##0")&" - "&TEXT(FLOOR(B6,5000)+4999,"£#,##0") -> £175,000 - £179,999 | N6: {=_xlfn.IFS(Sales_Export_2019_2020__2[[#This Row],[order_value_GBP]]>Summary!$E$3+Summary!$I$4,"Large",Sales_Export_2019_2020__2[[#This Row],[order_value_GBP]]<Summary!$E$3-Summary!$I$4,"Small",AND(Sales_Export_2019_2020__2[[#This Row],[order_value_GBP]]<Summary!$E$3+Summary!$I$4,Sales_Export_2019_2020__2[[#This Row],[order_value_GBP]]>Summary!$E$3-Summary!$I$4),"Average")} -> Large | O6: =FLOOR(Sales_Export_2019_2020__2[[#This Row],[order_value_GBP]],5000) -> 175000
A7: Spain | B7: 84900.24 | C7: 73701.9 | D7: 44026 | E7: Clothing | F7: Farrell, Swaniawski and Crist | G7: Emalia Dinse | H7: Perri Aldersley | I7: PC | J7: 60-6998932 | K7: =Sales_Export_2019_2020__2[[#This Row],[order_value_GBP]]-Sales_Export_2019_2020__2[[#This Row],[ cost ]] -> 11198.34 | L7: =COUNTIF(Sales_Export_2019_2020__2[order_id],Sales_Export_2019_2020__2[[#This Row],[order_id]])>1 -> FALSE | M7: =TEXT(FLOOR(B7,5000),"£#,##0")&" - "&TEXT(FLOOR(B7,5000)+4999,"£#,##0") -> £80,000 - £84,999 | N7: {=_xlfn.IFS(Sales_Export_2019_2020__2[[#This Row],[order_value_GBP]]>Summary!$E$3+Summary!$I$4,"Large",Sales_Export_2019_2020__2[[#This Row],[order_value_GBP]]<Summary!$E$3-Summary!$I$4,"Small",AND(Sales_Export_2019_2020__2[[#This Row],[order_value_GBP]]<Summary!$E$3+Summary!$I$4,Sales_Export_2019_2020__2[[#This Row],[order_value_GBP]]>Summary!$E$3-Summary!$I$4),"Average")} -> Average | O7: =FLOOR(Sales_Export_2019_2020__2[[#This Row],[order_value_GBP]],5000) -> 80000
A8: Portugal | B8: 71620.08 | C8: 62245.01 | D8: 43501 | E8: Books | F8: Schoen-Keeling | G8: Celine Tumasian | H8: Smitty Culverhouse | I8: PC | J8: 69-6259390 | K8: =Sales_Export_2019_2020__2[[#This Row],[order_value_GBP]]-Sales_Export_2019_2020__2[[#This Row],[ cost ]] -> 9375.07 | L8: =COUNTIF(Sales_Export_2019_2020__2[order_id],Sales_Export_2019_2020__2[[#This Row],[order_id]])>1 -> FALSE | M8: =TEXT(FLOOR(B8,5000),"£#,##0")&" - "&TEXT(FLOOR(B8,5000)+4999,"£#,##0") -> £70,000 - £74,999 | N8: {=_xlfn.IFS(Sales_Export_2019_2020__2[[#This Row],[order_value_GBP]]>Summary!$E$3+Summary!$I$4,"Large",Sales_Export_2019_2020__2[[#This Row],[order_value_GBP]]<Summary!$E$3-Summary!$I$4,"Small",AND(Sales_Export_2019_2020__2[[#This Row],[order_value_GBP]]<Summary!$E$3+Summary!$I$4,Sales_Export_2019_2020__2[[#This Row],[order_value_GBP]]>Summary!$E$3-Summary!$I$4),"Average")} -> Average | O8: =FLOOR(Sales_Export_2019_2020__2[[#This Row],[order_value_GBP]],5000) -> 70000
A9: UK | B9: 156585.22 | C9: 126599.15 | D9: 44073 | E9: Accessories | F9: Hermiston, Simonis and Wisoky | G9: Jessamine Apark | H9: Winny Agnolo | I9: PC | J9: 64-5761908 | K9: =Sales_Export_2019_2020__2[[#This Row],[order_value_GBP]]-Sales_Export_2019_2020__2[[#This Row],[ cost ]] -> 29986.07 | L9: =COUNTIF(Sales_Export_2019_2020__2[order_id],Sales_Export_2019_2020__2[[#This Row],[order_id]])>1 -> FALSE | M9: =TEXT(FLOOR(B9,5000),"£#,##0")&" - "&TEXT(FLOOR(B9,5000)+4999,"£#,##0") -> £155,000 - £159,999 | N9: {=_xlfn.IFS(Sales_Export_2019_2020__2[[#This Row],[order_value_GBP]]>Summary!$E$3+Summary!$I$4,"Large",Sales_Export_2019_2020__2[[#This Row],[order_value_GBP]]<Summary!$E$3-Summary!$I$4,"Small",AND(Sales_Export_2019_2020__2[[#This Row],[order_value_GBP]]<Summary!$E$3+Summary!$I$4,Sales_Export_2019_2020__2[[#This Row],[order_value_GBP]]>Summary!$E$3-Summary!$I$4),"Average")} -> Average | O9: =FLOOR(Sales_Export_2019_2020__2[[#This Row],[order_value_GBP]],5000) -> 155000
A10: Portugal | B10: 78461.13 | C10: 63537.82 | D10: 43961 | E10: Appliances | F10: Hessel-Stiedemann | G10: Celine Tumasian | H10: Smitty Culverhouse | I10: Mobile | J10: 91-4126746 | K10: =Sales_Export_2019_2020__2[[#This Row],[order_value_GBP]]-Sales_Export_2019_2020__2[[#This Row],[ cost ]] -> 14923.31 | L10: =COUNTIF(Sales_Export_2019_2020__2[order_id],Sales_Export_2019_2020__2[[#This Row],[order_id]])>1 -> FALSE | M10: =TEXT(FLOOR(B10,5000),"£#,##0")&" - "&TEXT(FLOOR(B10,5000)+4999,"£#,##0") -> £75,000 - £79,999 | N10: {=_xlfn.IFS(Sales_Export_2019_2020__2[[#This Row],[order_value_GBP]]>Summary!$E$3+Summary!$I$4,"Large",Sales_Export_2019_2020__2[[#This Row],[order_value_GBP]]<Summary!$E$3-Summary!$I$4,"Small",AND(Sales_Export_2019_2020__2[[#This Row],[order_value_GBP]]<Summary!$E$3+Summary!$I$4,Sales_Export_2019_2020__2[[#This Row],[order_value_GBP]]>Summary!$E$3-Summary!$I$4),"Average")} -> Average | O10: =FLOOR(Sales_Export_2019_2020__2[[#This Row],[order_value_GBP]],5000) -> 75000
A11: France | B11: 64827.8 | C11: 56043.63 | D11: 43485 | E11: Appliances | F11: Gislason-Stanton | G11: Othello Bowes | H11: Maighdiln Upcraft | I11: PC | J11: 62-3312495 | K11: =Sales_Export_2019_2020__2[[#This Row],[order_value_GBP]]-Sales_Export_2019_2020__2[[#This Row],[ cost ]] -> 8784.17 | L11: =COUNTIF(Sales_Export_2019_2020__2[order_id],Sales_Export_2019_2020__2[[#This Row],[order_id]])>1 -> FALSE | M11: =TEXT(FLOOR(B11,5000),"£#,##0")&" - "&TEXT(FLOOR(B11,5000)+4999,"£#,##0") -> £60,000 - £64,999 | N11: {=_xlfn.IFS(Sales_Export_2019_2020__2[[#This Row],[order_value_GBP]]>Summary!$E$3+Summary!$I$4,"Large",Sales_Export_2019_2020__2[[#This Row],[order_value_GBP]]<Summary!$E$3-Summary!$I$4,"Small",AND(Sales_Export_2019_2020__2[[#This Row],[order_value_GBP]]<Summary!$E$3+Summary!$I$4,Sales_Export_2019_2020__2[[#This Row],[order_value_GBP]]>Summary!$E$3-Summary!$I$4),"Average")} -> Average | O11: =FLOOR(Sales_Export_2019_2020__2[[#This Row],[order_value_GBP]],5000) -> 60000
A12: Sweden | B12: 142664.34 | C12: 120808.16 | D12: 43589 | E12: Appliances | F12: Swaniawski, Runolfsson and Green | G12: Maxie Marrow | H12: Madelon Bront | I12: PC | J12: 85-6625096 | K12: =Sales_Export_2019_2020__2[[#This Row],[order_value_GBP]]-Sales_Export_2019_2020__2[[#This Row],[ cost ]] -> 21856.18 | L12: =COUNTIF(Sales_Export_2019_2020__2[order_id],Sales_Export_2019_2020__2[[#This Row],[order_id]])>1 -> FALSE | M12: =TEXT(FLOOR(B12,5000),"£#,##0")&" - "&TEXT(FLOOR(B12,5000)+4999,"£#,##0") -> £140,000 - £144,999 | N12: {=_xlfn.IFS(Sales_Export_2019_2020__2[[#This Row],[order_value_GBP]]>Summary!$E$3+Summary!$I$4,"Large",Sales_Export_2019_2020__2[[#This Row],[order_value_GBP]]<Summary!$E$3-Summary!$I$4,"Small",AND(Sales_Export_2019_2020__2[[#This Row],[order_value_GBP]]<Summary!$E$3+Summary!$I$4,Sales_Export_2019_2020__2[[#This Row],[order_value_GBP]]>Summary!$E$3-Summary!$I$4),"Average")} -> Average | O12: =FLOOR(Sales_Export_2019_2020__2[[#This Row],[order_value_GBP]],5000) -> 140000
A13: UK | B13: 66673.19 | C13: 52811.83 | D13: 43519 | E13: Smartphones | F13: Gislason-Stanton | G13: Jessamine Apark | H13: Winny Agnolo | I13: PC | J13: 25-6368157 | K13: =Sales_Export_2019_2020__2[[#This Row],[order_value_GBP]]-Sales_Export_2019_2020__2[[#This Row],[ cost ]] -> 13861.36 | L13: =COUNTIF(Sales_Export_2019_2020__2[order_id],Sales_Export_2019_2020__2[[#This Row],[order_id]])>1 -> FALSE | M13: =TEXT(FLOOR(B13,5000),"£#,##0")&" - "&TEXT(FLOOR(B13,5000)+4999,"£#,##0") -> £65,000 - £69,999 | N13: {=_xlfn.IFS(Sales_Export_2019_2020__2[[#This Row],[order_value_GBP]]>Summary!$E$3+Summary!$I$4,"Large",Sales_Export_2019_2020__2[[#This Row],[order_value_GBP]]<Summary!$E$3-Summary!$I$4,"Small",AND(Sales_Export_2019_2020__2[[#This Row],[order_value_GBP]]<Summary!$E$3+Summary!$I$4,Sales_Export_2019_2020__2[[#This Row],[order_value_GBP]]>Summary!$E$3-Summary!$I$4),"Average")} -> Average | O13: =FLOOR(Sales_Export_2019_2020__2[[#This Row],[order_value_GBP]],5000) -> 65000
... A1001: Portugal | B1001: 107716.72 | C1001: 86679.64 | D1001: 43848 | E1001: Accessories | F1001: Jacobson, Marvin and Brown | G1001: Celine Tumasian | H1001: Brynn Dempster | I1001: Mobile | J1001: 61-3294149 | K1001: =Sales_Export_2019_2020__2[[#This Row],[order_value_GBP]]-Sales_Export_2019_2020__2[[#This Row],[ cost ]] -> 21037.08 | L1001: =COUNTIF(Sales_Export_2019_2020__2[order_id],Sales_Export_2019_2020__2[[#This Row],[order_id]])>1 -> FALSE | M1001: =TEXT(FLOOR(B1001,5000),"£#,##0")&" - "&TEXT(FLOOR(B1001,5000)+4999,"£#,##0") -> £105,000 - £109,999 | N1001: {=_xlfn.IFS(Sales_Export_2019_2020__2[[#This Row],[order_value_GBP]]>Summary!$E$3+Summary!$I$4,"Large",Sales_Export_2019_2020__2[[#This Row],[order_value_GBP]]<Summary!$E$3-Summary!$I$4,"Small",AND(Sales_Export_2019_2020__2[[#This Row],[order_value_GBP]]<Summary!$E$3+Summary!$I$4,Sales_Export_2019_2020__2[[#This Row],[order_value_GBP]]>Summary!$E$3-Summary!$I$4),"Average")} -> Average | O1001: =FLOOR(Sales_Export_2019_2020__2[[#This Row],[order_value_GBP]],5000) -> 105000

Sheet Summary
D1: Summary Table
C2: 2 | D2: 3 | E2: 4 | F2: 5 | G2: 6 | H2: 7 | I2: 8 | R2: Order Size Bin | S2: Count | T2: Bin Floor (sort key)
B3: Total Revenue | C3: =SUM(Sales_Export_2019_2020__2[order_value_GBP]) -> 1.1336174e+08 | D3: Avg Order Size | E3: =AVERAGE(Sales_Export_2019_2020__2[order_value_GBP]) -> 113361.74 | F3: Number of Categories | G3: =COUNTA(_xlfn.ANCHORARRAY(I9)) -> 10 | H3: Customer with the most orders | I3: =INDEX(B27:B101,MATCH(MAX($D$27:$D$101),D27:D101,0)) -> Johns and Sons | R3: {=_xlfn.XLOOKUP(_xlfn.ANCHORARRAY(T3),Sales_Export_2019_2020__2[Bin Floor],Sales_Export_2019_2020__2[Order Size Bin])} -> £15,000 - £19,999 | S3: {=COUNTIFS(Sales_Export_2019_2020__2[Bin Floor],_xlfn.ANCHORARRAY(T3))} -> 12 | T3: {=_xlfn._xlws.SORT(_xlfn.UNIQUE(Sales_Export_2019_2020__2[Bin Floor]))} -> 15000
B4: Total Cost | C4: =SUM(Sales_Export_2019_2020__2[[ cost ]]) -> 94369311 | D4: Largest Order | E4: =MAX(Sales_Export_2019_2020__2[order_value_GBP]) -> 383996.76 | F4: Number of Sales Reps | G4: =COUNTA(_xlfn.ANCHORARRAY(F9)) -> 35 | H4: STD of order size | I4: =_xlfn.STDEV.P(Sales_Export_2019_2020__2[order_value_GBP]) -> 61744.44 | R4: £20,000 - £24,999 | S4: 7 | T4: 20000
B5: Total Profit | C5: =SUM(Sales_Export_2019_2020__2[profit]) -> 18992428 | D5: Smallest Order | E5: =MIN(Sales_Export_2019_2020__2[order_value_GBP]) -> 15100.57 | F5: Number of Sales Managers | G5: =COUNTA(_xlfn.ANCHORARRAY(B10)) -> 15 | H5: Median Order Value | I5: =MEDIAN(Sales_Export_2019_2020__2[order_value_GBP]) -> 105419.43 | R5: £25,000 - £29,999 | S5: 20 | T5: 25000
B6: Number of Sales | C6: =ROWS(_xlfn.UNIQUE(Sales_Export_2019_2020__2[order_id])) -> 1000 | D6: Avg Profit per Order | E6: =C5/C6 -> 18992.428 | F6: Number of Customers | G6: =COUNTA(_xlfn.ANCHORARRAY(B27)) -> 75 | R6: £30,000 - £34,999 | S6: 19 | T6: 30000
R7: £35,000 - £39,999 | S7: 34 | T7: 35000
F8: Sales Rep | G8: Associated Sales Manager | I8: Categories | J8: Orders of each category | K8: Average Profit per Order | L8: Revenue per Order | M8: Cost per Order | N8: STD of order size | O8: Correlation between profit and order size | R8: £40,000 - £44,999 | S8: 30 | T8: 40000
B9: Sales Managers | C9: Number of Sales Reps | F9: {=_xlfn.UNIQUE(Sales_Export_2019_2020__2[sales_rep])} -> Madelon Bront | G9: =_xlfn.XLOOKUP(F9,Sales_Export_2019_2020__2[sales_rep],Sales_Export_2019_2020__2[sales_manager]) -> Maxie Marrow | I9: {=_xlfn.UNIQUE(Sales_Export_2019_2020__2[category])} -> Books | J9: =COUNTIF(Sales_Export_2019_2020__2[category],I9) -> 117 | K9: =AVERAGEIF(Sales_Export_2019_2020__2[category],I9,Sales_Export_2019_2020__2[profit]) -> 19024.905 | L9: =AVERAGEIF(Sales_Export_2019_2020__2[category],I9,Sales_Export_2019_2020__2[order_value_GBP]) -> 112649.39 | M9: =AVERAGEIF(Sales_Export_2019_2020__2[category],I9,Sales_Export_2019_2020__2[[ cost ]]) -> 93624.487 | N9: {=_xlfn.STDEV.P(_xlfn._xlws.FILTER(Sales_Export_2019_2020__2[order_value_GBP],Sales_Export_2019_2020__2[category]=I9))} -> 61004.334 | O9: {=CORREL(_xlfn._xlws.FILTER(Sales_Export_2019_2020__2[order_value_GBP],Sales_Export_2019_2020__2[category]=I9),_xlfn._xlws.FILTER(Sales_Export_2019_2020__2[profit],Sales_Export_2019_2020__2[category]=I9))} -> 0.93453593 | R9: £45,000 - £49,999 | S9: 26 | T9: 45000
B10: {=_xlfn.UNIQUE(Sales_Export_2019_2020__2[sales_manager])} -> Maxie Marrow | C10: =COUNTIF($G$9:$G$43,B10) -> 5 | F10: Wat Bowkley | G10: =_xlfn.XLOOKUP(F10,Sales_Export_2019_2020__2[sales_rep],Sales_Export_2019_2020__2[sales_manager]) -> Hube Corey | I10: Games | J10: =COUNTIF(Sales_Export_2019_2020__2[category],I10) -> 139 | K10: =AVERAGEIF(Sales_Export_2019_2020__2[category],I10,Sales_Export_2019_2020__2[profit]) -> 18415.797 | L10: =AVERAGEIF(Sales_Export_2019_2020__2[category],I10,Sales_Export_2019_2020__2[order_value_GBP]) -> 110227.51 | M10: =AVERAGEIF(Sales_Export_2019_2020__2[category],I10,Sales_Export_2019_2020__2[[ cost ]]) -> 91811.71 | N10: {=_xlfn.STDEV.P(_xlfn._xlws.FILTER(Sales_Export_2019_2020__2[order_value_GBP],Sales_Export_2019_2020__2[category]=I10))} -> 57187.476 | O10: {=CORREL(_xlfn._xlws.FILTER(Sales_Export_2019_2020__2[order_value_GBP],Sales_Export_2019_2020__2[category]=I10),_xlfn._xlws.FILTER(Sales_Export_2019_2020__2[profit],Sales_Export_2019_2020__2[category]=I10))} -> 0.9478257 | R10: £50,000 - £54,999 | S10: 31 | T10: 50000
B11: Hube Corey | C11: =COUNTIF($G$9:$G$43,B11) -> 2 | F11: Smitty Culverhouse | G11: =_xlfn.XLOOKUP(F11,Sales_Export_2019_2020__2[sales_rep],Sales_Export_2019_2020__2[sales_manager]) -> Celine Tumasian | I11: Clothing | J11: =COUNTIF(Sales_Export_2019_2020__2[category],I11) -> 155 | K11: =AVERAGEIF(Sales_Export_2019_2020__2[category],I11,Sales_Export_2019_2020__2[profit]) -> 18980.246 | L11: =AVERAGEIF(Sales_Export_2019_2020__2[category],I11,Sales_Export_2019_2020__2[order_value_GBP]) -> 113946.34 | M11: =AVERAGEIF(Sales_Export_2019_2020__2[category],I11,Sales_Export_2019_2020__2[[ cost ]]) -> 94966.091 | N11: {=_xlfn.STDEV.P(_xlfn._xlws.FILTER(Sales_Export_2019_2020__2[order_value_GBP],Sales_Export_2019_2020__2[category]=I11))} -> 64003.443 | O11: {=CORREL(_xlfn._xlws.FILTER(Sales_Export_2019_2020__2[order_value_GBP],Sales_Export_2019_2020__2[category]=I11),_xlfn._xlws.FILTER(Sales_Export_2019_2020__2[profit],Sales_Export_2019_2020__2[category]=I11))} -> 0.95203436 | R11: £55,000 - £59,999 | S11: 41 | T11: 55000
B12: Celine Tumasian | C12: =COUNTIF($G$9:$G$43,B12) -> 5 | F12: Aurelie Wren | G12: =_xlfn.XLOOKUP(F12,Sales_Export_2019_2020__2[sales_rep],Sales_Export_2019_2020__2[sales_manager]) -> Celine Tumasian | I12: Beauty | J12: =COUNTIF(Sales_Export_2019_2020__2[category],I12) -> 115 | K12: =AVERAGEIF(Sales_Export_2019_2020__2[category],I12,Sales_Export_2019_2020__2[profit]) -> 18421.108 | L12: =AVERAGEIF(Sales_Export_2019_2020__2[category],I12,Sales_Export_2019_2020__2[order_value_GBP]) -> 109296.21 | M12: =AVERAGEIF(Sales_Export_2019_2020__2[category],I12,Sales_Export_2019_2020__2[[ cost ]]) -> 90875.1 | N12: {=_xlfn.STDEV.P(_xlfn._xlws.FILTER(Sales_Export_2019_2020__2[order_value_GBP],Sales_Export_2019_2020__2[category]=I12))} -> 59060.631 | O12: {=CORREL(_xlfn._xlws.FILTER(Sales_Export_2019_2020__2[order_value_GBP],Sales_Export_2019_2020__2[category]=I12),_xlfn._xlws.FILTER(Sales_Export_2019_2020__2[profit],Sales_Export_2019_2020__2[category]=I12))} -> 0.94702137 | R12: £60,000 - £64,999 | S12: 25 | T12: 60000
B13: Emalia Dinse | C13: =COUNTIF($G$9:$G$43,B13) -> 3 | F13: Bertha Walbrook | G13: =_xlfn.XLOOKUP(F13,Sales_Export_2019_2020__2[sales_rep],Sales_Export_2019_2020__2[sales_manager]) -> Emalia Dinse | I13: Accessories | J13: =COUNTIF(Sales_Export_2019_2020__2[category],I13) -> 35 | K13: =AVERAGEIF(Sales_Export_2019_2020__2[category],I13,Sales_Export_2019_2020__2[profit]) -> 22397.038 | L13: =AVERAGEIF(Sales_Export_2019_2020__2[category],I13,Sales_Export_2019_2020__2[order_value_GBP]) -> 134398.02 | M13: =AVERAGEIF(Sales_Export_2019_2020__2[category],I13,Sales_Export_2019_2020__2[[ cost ]]) -> 112000.98 | N13: {=_xlfn.STDEV.P(_xlfn._xlws.FILTER(Sales_Export_2019_2020__2[order_value_GBP],Sales_Export_2019_2020__2[category]=I13))} -> 63784.53 | O13: {=CORREL(_xlfn._xlws.FILTER(Sales_Export_2019_2020__2[order_value_GBP],Sales_Export_2019_2020__2[category]=I13),_xlfn._xlws.FILTER(Sales_Export_2019_2020__2[profit],Sales_Export_2019_2020__2[category]=I13))} -> 0.92391288 | R13: £65,000 - £69,999 | S13: 35 | T13: 65000
B14: Jessamine Apark | C14: =COUNTIF($G$9:$G$43,B14) -> 3 | F14: Perri Aldersley | G14: =_xlfn.XLOOKUP(F14,Sales_Export_2019_2020__2[sales_rep],Sales_Export_2019_2020__2[sales_manager]) -> Emalia Dinse | I14: Appliances | J14: =COUNTIF(Sales_Export_2019_2020__2[category],I14) -> 131 | K14: =AVERAGEIF(Sales_Export_2019_2020__2[category],I14,Sales_Export_2019_2020__2[profit]) -> 19350.224 | L14: =AVERAGEIF(Sales_Export_2019_2020__2[category],I14,Sales_Export_2019_2020__2[order_value_GBP]) -> 115569.99 | M14: =AVERAGEIF(Sales_Export_2019_2020__2[category],I14,Sales_Export_2019_2020__2[[ cost ]]) -> 96219.766 | N14: {=_xlfn.STDEV.P(_xlfn._xlws.FILTER(Sales_Export_2019_2020__2[order_value_GBP],Sales_Export_2019_2020__2[category]=I14))} -> 62639.063 | O14: {=CORREL(_xlfn._xlws.FILTER(Sales_Export_2019_2020__2[order_value_GBP],Sales_Export_2019_2020__2[category]=I14),_xlfn._xlws.FILTER(Sales_Export_2019_2020__2[profit],Sales_Export_2019_2020__2[category]=I14))} -> 0.95461071 | R14: £70,000 - £74,999 | S14: 29 | T14: 70000
B15: Othello Bowes | C15: =COUNTIF($G$9:$G$43,B15) -> 5 | F15: Winny Agnolo | G15: =_xlfn.XLOOKUP(F15,Sales_Export_2019_2020__2[sales_rep],Sales_Export_2019_2020__2[sales_manager]) -> Jessamine Apark | I15: Smartphones | J15: =COUNTIF(Sales_Export_2019_2020__2[category],I15) -> 95 | K15: =AVERAGEIF(Sales_Export_2019_2020__2[category],I15,Sales_Export_2019_2020__2[profit]) -> 19164.712 | L15: =AVERAGEIF(Sales_Export_2019_2020__2[category],I15,Sales_Export_2019_2020__2[order_value_GBP]) -> 116859.52 | M15: =AVERAGEIF(Sales_Export_2019_2020__2[category],I15,Sales_Export_2019_2020__2[[ cost ]]) -> 97694.811 | N15: {=_xlfn.STDEV.P(_xlfn._xlws.FILTER(Sales_Export_2019_2020__2[order_value_GBP],Sales_Export_2019_2020__2[category]=I15))} -> 62201.29 | O15: {=CORREL(_xlfn._xlws.FILTER(Sales_Export_2019_2020__2[order_value_GBP],Sales_Export_2019_2020__2[category]=I15),_xlfn._xlws.FILTER(Sales_Export_2019_2020__2[profit],Sales_Export_2019_2020__2[category]=I15))} -> 0.94130651 | R15: £75,000 - £79,999 | S15: 35 | T15: 75000
B16: Denice Amberg | C16: =COUNTIF($G$9:$G$43,B16) -> 1 | F16: Maighdiln Upcraft | G16: =_xlfn.XLOOKUP(F16,Sales_Export_2019_2020__2[sales_rep],Sales_Export_2019_2020__2[sales_manager]) -> Othello Bowes | I16: Outdoors | J16: =COUNTIF(Sales_Export_2019_2020__2[category],I16) -> 50 | K16: =AVERAGEIF(Sales_Export_2019_2020__2[category],I16,Sales_Export_2019_2020__2[profit]) -> 21135.25 | L16: =AVERAGEIF(Sales_Export_2019_2020__2[category],I16,Sales_Export_2019_2020__2[order_value_GBP]) -> 118781.51 | M16: =AVERAGEIF(Sales_Export_2019_2020__2[category],I16,Sales_Export_2019_2020__2[[ cost ]]) -> 97646.259 | N16: {=_xlfn.STDEV.P(_xlfn._xlws.FILTER(Sales_Export_2019_2020__2[order_value_GBP],Sales_Export_2019_2020__2[category]=I16))} -> 58577.397 | O16: {=CORREL(_xlfn._xlws.FILTER(Sales_Export_2019_2020__2[order_value_GBP],Sales_Export_2019_2020__2[category]=I16),_xlfn._xlws.FILTER(Sales_Export_2019_2020__2[profit],Sales_Export_2019_2020__2[category]=I16))} -> 0.96207249 | R16: £80,000 - £84,999 | S16: 38 | T16: 80000
B17: Lambert Norheny | C17: =COUNTIF($G$9:$G$43,B17) -> 1 | F17: Genevra Charrisson | G17: =_xlfn.XLOOKUP(F17,Sales_Export_2019_2020__2[sales_rep],Sales_Export_2019_2020__2[sales_manager]) -> Jessamine Apark | I17: Electronics | J17: =COUNTIF(Sales_Export_2019_2020__2[category],I17) -> 134 | K17: =AVERAGEIF(Sales_Export_2019_2020__2[category],I17,Sales_Export_2019_2020__2[profit]) -> 17918.903 | L17: =AVERAGEIF(Sales_Export_2019_2020__2[category],I17,Sales_Export_2019_2020__2[order_value_GBP]) -> 108075.21 | M17: =AVERAGEIF(Sales_Export_2019_2020__2[category],I17,Sales_Export_2019_2020__2[[ cost ]]) -> 90156.303 | N17: {=_xlfn.STDEV.P(_xlfn._xlws.FILTER(Sales_Export_2019_2020__2[order_value_GBP],Sales_Export_2019_2020__2[category]=I17))} -> 57277.623 | O17: {=CORREL(_xlfn._xlws.FILTER(Sales_Export_2019_2020__2[order_value_GBP],Sales_Export_2019_2020__2[category]=I17),_xlfn._xlws.FILTER(Sales_Export_2019_2020__2[profit],Sales_Export_2019_2020__2[category]=I17))} -> 0.95132379 | R17: £85,000 - £89,999 | S17: 37 | T17: 85000
B18: Charil Alpe | C18: =COUNTIF($G$9:$G$43,B18) -> 2 | F18: Anita Woakes | G18: =_xlfn.XLOOKUP(F18,Sales_Export_2019_2020__2[sales_rep],Sales_Export_2019_2020__2[sales_manager]) -> Maxie Marrow | I18: Other | J18: =COUNTIF(Sales_Export_2019_2020__2[category],I18) -> 29 | K18: =AVERAGEIF(Sales_Export_2019_2020__2[category],I18,Sales_Export_2019_2020__2[profit]) -> 18932.197 | L18: =AVERAGEIF(Sales_Export_2019_2020__2[category],I18,Sales_Export_2019_2020__2[order_value_GBP]) -> 112516.66 | M18: =AVERAGEIF(Sales_Export_2019_2020__2[category],I18,Sales_Export_2019_2020__2[[ cost ]]) -> 93584.465 | N18: {=_xlfn.STDEV.P(_xlfn._xlws.FILTER(Sales_Export_2019_2020__2[order_value_GBP],Sales_Export_2019_2020__2[category]=I18))} -> 88131.727 | O18: {=CORREL(_xlfn._xlws.FILTER(Sales_Export_2019_2020__2[order_value_GBP],Sales_Export_2019_2020__2[category]=I18),_xlfn._xlws.FILTER(Sales_Export_2019_2020__2[profit],Sales_Export_2019_2020__2[category]=I18))} -> 0.97466059 | R18: £90,000 - £94,999 | S18: 21 | T18: 90000
B19: Ilsa Kob | C19: =COUNTIF($G$9:$G$43,B19) -> 1 | F19: Amelina Piscopiello | G19: =_xlfn.XLOOKUP(F19,Sales_Export_2019_2020__2[sales_rep],Sales_Export_2019_2020__2[sales_manager]) -> Othello Bowes | R19: £95,000 - £99,999 | S19: 33 | T19: 95000
B20: Piggy Roscrigg | C20: =COUNTIF($G$9:$G$43,B20) -> 1 | F20: Jay Morefield | G20: =_xlfn.XLOOKUP(F20,Sales_Export_2019_2020__2[sales_rep],Sales_Export_2019_2020__2[sales_manager]) -> Jessamine Apark | I20: Year | J20: Total Revenue | K20: Total Sales | L20: Share of Revenue | M20: Difference in share of profits and sales | N20: Avg Profit per Sale | O20: Profit Margin | P20: Total Profit | R20: £100,000 - £104,999 | S20: 24 | T20: 100000
B21: Glenine Suttaby | C21: =COUNTIF($G$9:$G$43,B21) -> 2 | F21: Corene Shirer | G21: =_xlfn.XLOOKUP(F21,Sales_Export_2019_2020__2[sales_rep],Sales_Export_2019_2020__2[sales_manager]) -> Celine Tumasian | I21: 2019 | J21: 56617524 | K21: 490 | L21: 0.49944121 | M21: 0.0095294983 | N21: 19361.792 | O21: 0.16756787 | P21: 9487277.9 | R21: £105,000 - £109,999 | S21: 32 | T21: 105000
B22: Rickard Doogood | C22: =COUNTIF($G$9:$G$43,B22) -> 1 | F22: Alyosha Meah | G22: =_xlfn.XLOOKUP(F22,Sales_Export_2019_2020__2[sales_rep],Sales_Export_2019_2020__2[sales_manager]) -> Maxie Marrow | I22: 2020 | J22: 56744214 | K22: 510 | L22: 0.50055879 | M22: -0.0095294983 | N22: 18637.549 | O22: 0.1675087 | P22: 9505149.8 | R22: £110,000 - £114,999 | S22: 21 | T22: 110000
B23: Modestia Byfford | C23: =COUNTIF($G$9:$G$43,B23) -> 2 | F23: Nero Harbisher | G23: =_xlfn.XLOOKUP(F23,Sales_Export_2019_2020__2[sales_rep],Sales_Export_2019_2020__2[sales_manager]) -> Denice Amberg | I23: Grand Total | J23: 1.1336174e+08 | K23: 1000 | L23: 1 | M23: 0 | N23: 18992.428 | O23: 0.16753825 | P23: 18992428 | R23: £115,000 - £119,999 | S23: 34 | T23: 115000
B24: Orsa Geekin | C24: =COUNTIF($G$9:$G$43,B24) -> 1 | F24: Hortense Gerring | G24: =_xlfn.XLOOKUP(F24,Sales_Export_2019_2020__2[sales_rep],Sales_Export_2019_2020__2[sales_manager]) -> Celine Tumasian | R24: £120,000 - £124,999 | S24: 35 | T24: 120000
F25: Collin Mackness | G25: =_xlfn.XLOOKUP(F25,Sales_Export_2019_2020__2[sales_rep],Sales_Export_2019_2020__2[sales_manager]) -> Lambert Norheny | R25: £125,000 - £129,999 | S25: 32 | T25: 125000
B26: Customers | C26: Avg Order Size | D26: Number of Orders | F26: Shermy McGready | G26: =_xlfn.XLOOKUP(F26,Sales_Export_2019_2020__2[sales_rep],Sales_Export_2019_2020__2[sales_manager]) -> Charil Alpe | R26: £130,000 - £134,999 | S26: 24 | T26: 130000
B27: {=_xlfn.UNIQUE(Sales_Export_2019_2020__2[customer_name])} -> Goldner-Dibbert | C27: =AVERAGEIF(Sales_Export_2019_2020__2[customer_name],B27,Sales_Export_2019_2020__2[order_value_GBP]) -> 100941.25 | D27: =COUNTIF(Sales_Export_2019_2020__2[customer_name],B27) -> 9 | F27: Jocelyn Laurentino | G27: =_xlfn.XLOOKUP(F27,Sales_Export_2019_2020__2[sales_rep],Sales_Export_2019_2020__2[sales_manager]) -> Ilsa Kob | R27: £135,000 - £139,999 | S27: 21 | T27: 135000
B28: Hilll-Vandervort | C28: =AVERAGEIF(Sales_Export_2019_2020__2[customer_name],B28,Sales_Export_2019_2020__2[order_value_GBP]) -> 114416.18 | D28: =COUNTIF(Sales_Export_2019_2020__2[customer_name],B28) -> 16 | F28: Caro Morfield | G28: =_xlfn.XLOOKUP(F28,Sales_Export_2019_2020__2[sales_rep],Sales_Export_2019_2020__2[sales_manager]) -> Maxie Marrow | R28: £140,000 - £144,999 | S28: 22 | T28: 140000
B29: Larkin-Collier | C29: =AVERAGEIF(Sales_Export_2019_2020__2[customer_name],B29,Sales_Export_2019_2020__2[order_value_GBP]) -> 122216.66 | D29: =COUNTIF(Sales_Export_2019_2020__2[customer_name],B29) -> 21 | F29: Crysta Halls | G29: =_xlfn.XLOOKUP(F29,Sales_Export_2019_2020__2[sales_rep],Sales_Export_2019_2020__2[sales_manager]) -> Othello Bowes | R29: £145,000 - £149,999 | S29: 27 | T29: 145000
B30: Hessel-Stiedemann | C30: =AVERAGEIF(Sales_Export_2019_2020__2[customer_name],B30,Sales_Export_2019_2020__2[order_value_GBP]) -> 118401.16 | D30: =COUNTIF(Sales_Export_2019_2020__2[customer_name],B30) -> 55 | F30: Ora Grennan | G30: =_xlfn.XLOOKUP(F30,Sales_Export_2019_2020__2[sales_rep],Sales_Export_2019_2020__2[sales_manager]) -> Othello Bowes | R30: £150,000 - £154,999 | S30: 25 | T30: 150000
B31: Johns and Sons | C31: =AVERAGEIF(Sales_Export_2019_2020__2[customer_name],B31,Sales_Export_2019_2020__2[order_value_GBP]) -> 115213.08 | D31: =COUNTIF(Sales_Export_2019_2020__2[customer_name],B31) -> 142 | F31: Joshua Prevost | G31: =_xlfn.XLOOKUP(F31,Sales_Export_2019_2020__2[sales_rep],Sales_Export_2019_2020__2[sales_manager]) -> Piggy Roscrigg | R31: £155,000 - £159,999 | S31: 24 | T31: 155000
B32: Farrell, Swaniawski and Crist | C32: =AVERAGEIF(Sales_Export_2019_2020__2[customer_name],B32,Sales_Export_2019_2020__2[order_value_GBP]) -> 94214.645 | D32: =COUNTIF(Sales_Export_2019_2020__2[customer_name],B32) -> 17 | F32: Avrit Chanders | G32: =_xlfn.XLOOKUP(F32,Sales_Export_2019_2020__2[sales_rep],Sales_Export_2019_2020__2[sales_manager]) -> Othello Bowes | R32: £160,000 - £164,999 | S32: 25 | T32: 160000
B33: Schoen-Keeling | C33: =AVERAGEIF(Sales_Export_2019_2020__2[customer_name],B33,Sales_Export_2019_2020__2[order_value_GBP]) -> 83383.017 | D33: =COUNTIF(Sales_Export_2019_2020__2[customer_name],B33) -> 10 | F33: Bernadine Fullagar | G33: =_xlfn.XLOOKUP(F33,Sales_Export_2019_2020__2[sales_rep],Sales_Export_2019_2020__2[sales_manager]) -> Charil Alpe | R33: £165,000 - £169,999 | S33: 26 | T33: 165000
B34: Hermiston, Simonis and Wisoky | C34: =AVERAGEIF(Sales_Export_2019_2020__2[customer_name],B34,Sales_Export_2019_2020__2[order_value_GBP]) -> 107191.42 | D34: =COUNTIF(Sales_Export_2019_2020__2[customer_name],B34) -> 10 | F34: Tarrah Castelletti | G34: =_xlfn.XLOOKUP(F34,Sales_Export_2019_2020__2[sales_rep],Sales_Export_2019_2020__2[sales_manager]) -> Maxie Marrow | R34: £170,000 - £174,999 | S34: 25 | T34: 170000
B35: Gislason-Stanton | C35: =AVERAGEIF(Sales_Export_2019_2020__2[customer_name],B35,Sales_Export_2019_2020__2[order_value_GBP]) -> 118254.4 | D35: =COUNTIF(Sales_Export_2019_2020__2[customer_name],B35) -> 17 | F35: Bunnie Tonbridge | G35: =_xlfn.XLOOKUP(F35,Sales_Export_2019_2020__2[sales_rep],Sales_Export_2019_2020__2[sales_manager]) -> Glenine Suttaby | R35: £175,000 - £179,999 | S35: 22 | T35: 175000
B36: Swaniawski, Runolfsson and Green | C36: =AVERAGEIF(Sales_Export_2019_2020__2[customer_name],B36,Sales_Export_2019_2020__2[order_value_GBP]) -> 100245.38 | D36: =COUNTIF(Sales_Export_2019_2020__2[customer_name],B36) -> 25 | F36: Palm Wetherald | G36: =_xlfn.XLOOKUP(F36,Sales_Export_2019_2020__2[sales_rep],Sales_Export_2019_2020__2[sales_manager]) -> Glenine Suttaby | R36: £180,000 - £184,999 | S36: 8 | T36: 180000
B37: Wisoky Inc | C37: =AVERAGEIF(Sales_Export_2019_2020__2[customer_name],B37,Sales_Export_2019_2020__2[order_value_GBP]) -> 108462.59 | D37: =COUNTIF(Sales_Export_2019_2020__2[customer_name],B37) -> 21 | F37: Casie MacBain | G37: =_xlfn.XLOOKUP(F37,Sales_Export_2019_2020__2[sales_rep],Sales_Export_2019_2020__2[sales_manager]) -> Rickard Doogood | R37: £185,000 - £189,999 | S37: 4 | T37: 185000
B38: Tillman and Sons | C38: =AVERAGEIF(Sales_Export_2019_2020__2[customer_name],B38,Sales_Export_2019_2020__2[order_value_GBP]) -> 99014.511 | D38: =COUNTIF(Sales_Export_2019_2020__2[customer_name],B38) -> 21 | F38: Brynn Dempster | G38: =_xlfn.XLOOKUP(F38,Sales_Export_2019_2020__2[sales_rep],Sales_Export_2019_2020__2[sales_manager]) -> Celine Tumasian | R38: £190,000 - £194,999 | S38: 4 | T38: 190000
B39: Rowe, Hermiston and Kessler | C39: =AVERAGEIF(Sales_Export_2019_2020__2[customer_name],B39,Sales_Export_2019_2020__2[order_value_GBP]) -> 105114.77 | D39: =COUNTIF(Sales_Export_2019_2020__2[customer_name],B39) -> 22 | F39: Case Desorts | G39: =_xlfn.XLOOKUP(F39,Sales_Export_2019_2020__2[sales_rep],Sales_Export_2019_2020__2[sales_manager]) -> Modestia Byfford | R39: £195,000 - £199,999 | S39: 3 | T39: 195000
... B43: Jacobson, Marvin and Brown | C43: =AVERAGEIF(Sales_Export_2019_2020__2[customer_name],B43,Sales_Export_2019_2020__2[order_value_GBP]) -> 155424 | D43: =COUNTIF(Sales_Export_2019_2020__2[customer_name],B43) -> 7 | F43: Cobby Andersen | G43: =_xlfn.XLOOKUP(F43,Sales_Export_2019_2020__2[sales_rep],Sales_Export_2019_2020__2[sales_manager]) -> Modestia Byfford | R43: £215,000 - £219,999 | S43: 2 | T43: 215000
...

Sheet MOMP Tables
W1: Monthly Ratings
C2: Monthly Summary | P2: Yearly Supporting Statistics | Q2: 2019 | R2: 2020 | S2: Total | W2: 2019 | X2: 2020 | AF2: Product Summary
C3: 2019 | G3: 2020 | K3: Total Orders | L3: Total Revenue | M3: Total Cost | N3: Total Profit | V3: Jan | W3: {=IF(INDEX(W$21:W$32,_xlfn.XMATCH($V3,$V$21:$V$32,0))<$S$19,"Below Average",IF(INDEX(W$21:W$32,_xlfn.XMATCH($V21,$V$21:$V$32,0))>$S$21,"Above Average", "Average"))} -> Average | X3: {=IF(INDEX(X$21:X$32,_xlfn.XMATCH($V3,$V$21:$V$32,0))<$S$19,"Below Average",IF(INDEX(X$21:X$32,_xlfn.XMATCH($V21,$V$21:$V$32,0))>$S$21,"Above Average", "Average"))} -> Average | AF3: 2019 | AJ3: 2020 | AN3: Total Total Number of Sales | AO3: Total Average Cost | AP3: Total Average Order Value | AQ3: Total Average of Profit
B4: Month | C4: Orders | D4: Revenue | E4: Cost | F4: Profit | G4: Orders | H4: Revenue | I4: Cost | J4: Profit | P4: Correlation between orders and profits | Q4: =CORREL(C5:C16,F5:F16) -> 0.45204688 | R4: =CORREL(G5:G16,J5:J16) -> 0.37399861 | S4: =CORREL(K5:K16,N5:N16) -> 0.14238539 | V4: Feb | W4: {=IF(INDEX($W$21:$W$32,_xlfn.XMATCH(V4,$V$21:$V$32,0))<$S$19,"Below Average",IF(INDEX($W$21:$W$32,_xlfn.XMATCH(V22,$V$21:$V$32,0))>$S$21,"Above Average", "Average"))} -> Average | X4: {=IF(INDEX(X$21:X$32,_xlfn.XMATCH($V4,$V$21:$V$32,0))<$S$19,"Below Average",IF(INDEX(X$21:X$32,_xlfn.XMATCH($V22,$V$21:$V$32,0))>$S$21,"Above Average", "Average"))} -> Below Average | AE4: Category Breakdown | AF4: Total Number of Sales | AG4: Average Cost | AH4: Average Order Value | AI4: Average of Profit | AJ4: Total Number of Sales | AK4: Average Cost | AL4: Average Order Value | AM4: Average of Profit
B5: Jan | C5: 44 | D5: 4516614.8 | E5: 3792383.5 | F5: 724231.31 | G5: 51 | H5: 5215699.8 | I5: 4291060.8 | J5: 924639.02 | K5: 95 | L5: 9732314.7 | M5: 8083444.3 | N5: 1648870.3 | P5: Standard Deviation of Profit Margin (Percentage Points) | Q5: =100*_xlfn.STDEV.P(Q39:Q50) -> 0.40545845 | R5: =100*_xlfn.STDEV.P(R39:R50) -> 0.52165337 | S5: =_xlfn.STDEV.P(S39:S50) -> 0.0024180522 | V5: Mar | W5: {=IF(INDEX($W$21:$W$32,_xlfn.XMATCH(V5,$V$21:$V$32,0))<$S$19,"Below Average",IF(INDEX($W$21:$W$32,_xlfn.XMATCH(V23,$V$21:$V$32,0))>$S$21,"Above Average", "Average"))} -> Below Average | X5: {=IF(INDEX(X$21:X$32,_xlfn.XMATCH($V5,$V$21:$V$32,0))<$S$19,"Below Average",IF(INDEX(X$21:X$32,_xlfn.XMATCH($V23,$V$21:$V$32,0))>$S$21,"Above Average", "Average"))} -> Average | AE5: Accessories | AF5: 16 | AG5: 115805.45 | AH5: 139551.06 | AI5: 23745.609 | AJ5: 19 | AK5: 108797.22 | AL5: 130058.61 | AM5: 21261.399 | AN5: 35 | AO5: 112000.98 | AP5: 134398.02 | AQ5: 22397.038
B6: Feb | C6: 44 | D6: 2895563.9 | E6: 2402359 | F6: 493204.9 | G6: 28 | H6: 1959413 | I6: 1643662.5 | J6: 315750.51 | K6: 72 | L6: 4854976.9 | M6: 4046021.5 | N6: 808955.41 | P6: Standard Deviation of Orders | Q6: =_xlfn.STDEV.P(C5:C16) -> 5.2413951 | R6: =_xlfn.STDEV.P(G5:G16) -> 8.2815055 | S6: =_xlfn.STDEV.P(K5:K16) -> 8.4294457 | V6: Apr | W6: {=IF(INDEX($W$21:$W$32,_xlfn.XMATCH(V6,$V$21:$V$32,0))<$S$19,"Below Average",IF(INDEX($W$21:$W$32,_xlfn.XMATCH(V24,$V$21:$V$32,0))>$S$21,"Above Average", "Average"))} -> Average | X6: {=IF(INDEX(X$21:X$32,_xlfn.XMATCH($V6,$V$21:$V$32,0))<$S$19,"Below Average",IF(INDEX(X$21:X$32,_xlfn.XMATCH($V24,$V$21:$V$32,0))>$S$21,"Above Average", "Average"))} -> Average | AE6: Appliances | AF6: 62 | AG6: 95395.716 | AH6: 114719.13 | AI6: 19323.413 | AJ6: 69 | AK6: 96960.217 | AL6: 116334.53 | AM6: 19374.315 | AN6: 131 | AO6: 96219.766 | AP6: 115569.99 | AQ6: 19350.224
B7: Mar | C7: 41 | D7: 2521828 | E7: 2092407.4 | F7: 429420.62 | G7: 52 | H7: 3579943.8 | I7: 2983600.1 | J7: 596343.77 | K7: 93 | L7: 6101771.8 | M7: 5076007.4 | N7: 1025764.4 | P7: Avg in Difference between profit and sales share | Q7: =AVERAGE(H38:H49) -> 0.00079412486 | R7: =AVERAGE(I38:I49) -> -0.00079412486 | S7: 0 | V7: May | W7: {=IF(INDEX($W$21:$W$32,_xlfn.XMATCH(V7,$V$21:$V$32,0))<$S$19,"Below Average",IF(INDEX($W$21:$W$32,_xlfn.XMATCH(V25,$V$21:$V$32,0))>$S$21,"Above Average", "Average"))} -> Average | X7: {=IF(INDEX(X$21:X$32,_xlfn.XMATCH($V7,$V$21:$V$32,0))<$S$19,"Below Average",IF(INDEX(X$21:X$32,_xlfn.XMATCH($V25,$V$21:$V$32,0))>$S$21,"Above Average", "Average"))} -> Average | AE7: Beauty | AF7: 61 | AG7: 99161.231 | AH7: 118270.98 | AI7: 19109.75 | AJ7: 54 | AK7: 81514.839 | AL7: 99158.037 | AM7: 17643.197 | AN7: 115 | AO7: 90875.1 | AP7: 109296.21 | AQ7: 18421.108
B8: Apr | C8: 36 | D8: 4172236.8 | E8: 3479483.1 | F8: 692753.62 | G8: 38 | H8: 4069097.8 | I8: 3372878.3 | J8: 696219.46 | K8: 74 | L8: 8241334.5 | M8: 6852361.5 | N8: 1388973.1 | P8: STD of profit share - sales share | Q8: =_xlfn.STDEV.P(H38:H49) -> 0.015481995 | R8: =_xlfn.STDEV.P(I38:I49) -> 0.010967011 | S8: =_xlfn.STDEV.P(J38:J49) -> 0.02596975 | V8: Jun | W8: {=IF(INDEX($W$21:$W$32,_xlfn.XMATCH(V8,$V$21:$V$32,0))<$S$19,"Below Average",IF(INDEX($W$21:$W$32,_xlfn.XMATCH(V26,$V$21:$V$32,0))>$S$21,"Above Average", "Average"))} -> Above Average | X8: {=IF(INDEX(X$21:X$32,_xlfn.XMATCH($V8,$V$21:$V$32,0))<$S$19,"Below Average",IF(INDEX(X$21:X$32,_xlfn.XMATCH($V26,$V$21:$V$32,0))>$S$21,"Above Average", "Average"))} -> Above Average | AE8: Books | AF8: 46 | AG8: 96982.911 | AH8: 117734.88 | AI8: 20751.97 | AJ8: 71 | AK8: 91448.607 | AL8: 109354.57 | AM8: 17905.962 | AN8: 117 | AO8: 93624.487 | AP8: 112649.39 | AQ8: 19024.905
B9: May | C9: 38 | D9: 3825682 | E9: 3177423.7 | F9: 648258.3 | G9: 55 | H9: 5537943.8 | I9: 4623092.1 | J9: 914851.65 | K9: 93 | L9: 9363625.7 | M9: 7800515.8 | N9: 1563109.9 | P9: Correlation between avg order val and avg profit per sale | V9: Jul | W9: {=IF(INDEX($W$21:$W$32,_xlfn.XMATCH(V9,$V$21:$V$32,0))<$S$19,"Below Average",IF(INDEX($W$21:$W$32,_xlfn.XMATCH(V27,$V$21:$V$32,0))>$S$21,"Above Average", "Average"))} -> Average | X9: {=IF(INDEX(X$21:X$32,_xlfn.XMATCH($V9,$V$21:$V$32,0))<$S$19,"Below Average",IF(INDEX(X$21:X$32,_xlfn.XMATCH($V27,$V$21:$V$32,0))>$S$21,"Above Average", "Average"))} -> Average | AE9: Clothing | AF9: 85 | AG9: 100050.27 | AH9: 119936.93 | AI9: 19886.657 | AJ9: 70 | AK9: 88792.446 | AL9: 106672.05 | AM9: 17879.604 | AN9: 155 | AO9: 94966.091 | AP9: 113946.34 | AQ9: 18980.246
B10: Jun | C10: 47 | D10: 7692234.9 | E10: 6386956.5 | F10: 1305278.4 | G10: 43 | H10: 7158137.9 | I10: 5971093.4 | J10: 1187044.5 | K10: 90 | L10: 14850373 | M10: 12358050 | N10: 2492322.8 | P10: Correlation between avg order val and avg profit per sale | Q10: =CORREL(M21:M32,C38:C49) -> 0.99727848 | R10: =CORREL(D38:D49,N21:N32) -> 0.99455161 | V10: Aug | W10: {=IF(INDEX($W$21:$W$32,_xlfn.XMATCH(V10,$V$21:$V$32,0))<$S$19,"Below Average",IF(INDEX($W$21:$W$32,_xlfn.XMATCH(V28,$V$21:$V$32,0))>$S$21,"Above Average", "Average"))} -> Average | X10: {=IF(INDEX(X$21:X$32,_xlfn.XMATCH($V10,$V$21:$V$32,0))<$S$19,"Below Average",IF(INDEX(X$21:X$32,_xlfn.XMATCH($V28,$V$21:$V$32,0))>$S$21,"Above Average", "Average"))} -> Average | AE10: Electronics | AF10: 68 | AG10: 83612.752 | AH10: 100864.41 | AI10: 17251.656 | AJ10: 66 | AK10: 96898.143 | AL10: 115504.51 | AM10: 18606.37 | AN10: 134 | AO10: 90156.303 | AP10: 108075.21 | AQ10: 17918.903
B11: Jul | C11: 40 | D11: 6638609.2 | E11: 5554381.8 | F11: 1084227.4 | G11: 36 | H11: 5242556.5 | I11: 4402567.1 | J11: 839989.39 | K11: 76 | L11: 11881166 | M11: 9956948.9 | N11: 1924216.8 | P11: Avg Monthly Profit | Q11: =AVERAGE(F5:F16) -> 790606.49 | R11: =AVERAGE(J5:J16) -> 792095.82 | S11: =AVERAGE(N5:N16) -> 1582702.3 | V11: Sep | W11: {=IF(INDEX($W$21:$W$32,_xlfn.XMATCH(V11,$V$21:$V$32,0))<$S$19,"Below Average",IF(INDEX($W$21:$W$32,_xlfn.XMATCH(V29,$V$21:$V$32,0))>$S$21,"Above Average", "Average"))} -> Average | X11: {=IF(INDEX(X$21:X$32,_xlfn.XMATCH($V11,$V$21:$V$32,0))<$S$19,"Below Average",IF(INDEX(X$21:X$32,_xlfn.XMATCH($V29,$V$21:$V$32,0))>$S$21,"Above Average", "Average"))} -> Average | AE11: Games | AF11: 74 | AG11: 91794.38 | AH11: 109785.44 | AI11: 17991.058 | AJ11: 65 | AK11: 91831.439 | AL11: 110730.78 | AM11: 18899.345 | AN11: 139 | AO11: 91811.71 | AP11: 110227.51 | AQ11: 18415.797
B12: Aug | C12: 31 | D12: 3437450.1 | E12: 2857134 | F12: 580316.12 | G12: 45 | H12: 4714525.2 | I12: 3945548.9 | J12: 768976.36 | K12: 76 | L12: 8151975.3 | M12: 6802682.9 | N12: 1349292.5 | P12: STD of monthly profit | Q12: =_xlfn.STDEV.P(F5:F16) -> 325312.74 | R12: =_xlfn.STDEV.P(J5:J16) -> 207506.54 | S12: =_xlfn.STDEV.P(N5:N16) -> 489875 | V12: Oct | W12: {=IF(INDEX($W$21:$W$32,_xlfn.XMATCH(V12,$V$21:$V$32,0))<$S$19,"Below Average",IF(INDEX($W$21:$W$32,_xlfn.XMATCH(V30,$V$21:$V$32,0))>$S$21,"Above Average", "Average"))} -> Average | X12: {=IF(INDEX(X$21:X$32,_xlfn.XMATCH($V12,$V$21:$V$32,0))<$S$19,"Below Average",IF(INDEX(X$21:X$32,_xlfn.XMATCH($V30,$V$21:$V$32,0))>$S$21,"Above Average", "Average"))} -> Average | AE12: Other | AF12: 10 | AG12: 98834.291 | AH12: 120111.05 | AI12: 21276.763 | AJ12: 19 | AK12: 90821.399 | AL12: 108519.61 | AM12: 17698.215 | AN12: 29 | AO12: 93584.465 | AP12: 112516.66 | AQ12: 18932.197
B13: Sep | C13: 49 | D13: 4870060.5 | E13: 4081869 | F13: 788191.58 | G13: 34 | H13: 3778141.4 | I13: 3114973.7 | J13: 663167.65 | K13: 83 | L13: 8648201.9 | M13: 7196842.7 | N13: 1451359.2 | P13: Corr between total sales and avg profit per sale | Q13: =CORREL(AB21:AB32,C38:C49) -> 0.17781761 | R13: =CORREL(AC21:AC32,D38:D49) -> -0.27722849 | V13: Nov | W13: {=IF(INDEX($W$21:$W$32,_xlfn.XMATCH(V13,$V$21:$V$32,0))<$S$19,"Below Average",IF(INDEX($W$21:$W$32,_xlfn.XMATCH(V31,$V$21:$V$32,0))>$S$21,"Above Average", "Average"))} -> Average | X13: {=IF(INDEX(X$21:X$32,_xlfn.XMATCH($V13,$V$21:$V$32,0))<$S$19,"Below Average",IF(INDEX(X$21:X$32,_xlfn.XMATCH($V31,$V$21:$V$32,0))>$S$21,"Above Average", "Average"))} -> Average | AE13: Outdoors | AF13: 21 | AG13: 90273.627 | AH13: 109635.75 | AI13: 19362.128 | AJ13: 29 | AK13: 102985.06 | AL13: 125404.3 | AM13: 22419.236 | AN13: 50 | AO13: 97646.259 | AP13: 118781.51 | AQ13: 21135.25
B14: Oct | C14: 43 | D14: 4372149.5 | E14: 3627715.1 | F14: 744434.48 | G14: 50 | H14: 4869726.8 | I14: 4030025.9 | J14: 839700.96 | K14: 93 | L14: 9241876.4 | M14: 7657741 | N14: 1584135.4 | V14: Dec | W14: {=IF(INDEX($W$21:$W$32,_xlfn.XMATCH(V14,$V$21:$V$32,0))<$S$19,"Below Average",IF(INDEX($W$21:$W$32,_xlfn.XMATCH(V32,$V$21:$V$32,0))>$S$21,"Above Average", "Average"))} -> Above Average | X14: {=IF(INDEX(X$21:X$32,_xlfn.XMATCH($V14,$V$21:$V$32,0))<$S$19,"Below Average",IF(INDEX(X$21:X$32,_xlfn.XMATCH($V32,$V$21:$V$32,0))>$S$21,"Above Average", "Average"))} -> Average | AE14: Smartphones | AF14: 47 | AG14: 106084.31 | AH14: 126825.21 | AI14: 20740.896 | AJ14: 48 | AK14: 89480.091 | AL14: 107101.46 | AM14: 17621.366 | AN14: 95 | AO14: 97694.811 | AP14: 116859.52 | AQ14: 19164.712
B15: Nov | C15: 33 | D15: 2961318.6 | E15: 2479031 | F15: 482287.62 | G15: 45 | H15: 4734730.1 | I15: 3947059.7 | J15: 787670.37 | K15: 78 | L15: 7696048.7 | M15: 6426090.7 | N15: 1269958 | Q15: =Q11+Q12 -> 1115919.2 | R15: =SUM(R11,R12) -> 999602.36 | AE15: Grand Total | AF15: 490 | AG15: 96184.177 | AH15: 115545.97 | AI15: 19361.792 | AJ15: 510 | AK15: 92625.617 | AL15: 111263.17 | AM15: 18637.549 | AN15: 1000 | AO15: 94369.311 | AP15: 113361.74 | AQ15: 18992.428
B16: Dec | C16: 44 | D16: 8713776 | E16: 7199102.5 | F16: 1514673.6 | G16: 33 | H16: 5884298.3 | I16: 4913502 | J16: 970796.22 | K16: 77 | L16: 14598074 | M16: 12112605 | N16: 2485469.8
B17: Grand Total | C17: 490 | D17: 56617524 | E17: 47130247 | F17: 9487277.9 | G17: 510 | H17: 56744214 | I17: 47239064 | J17: 9505149.8 | K17: 1000 | L17: 1.1336174e+08 | M17: 94369311 | N17: 18992428
S18: 2019 | T18: 2020 | AF18: Categories by Month
B19: Monthly Revenue | C19: Year | L19: Average Order Value by Month | M19: Year | R19: Below Average | S19: =Q11-Q12 -> 465293.75 | T19: =R11-R12 -> 584589.28 | V19: Profit per Month | W19: Column Labels | AA19: Sales by Month | AB19: Year | AF19: Jan | AJ19: Feb | AN19: Mar | AR19: Apr | AV19: May | AZ19: Jun | BD19: Jul | BH19: Aug | BL19: Sep | BP19: Oct | BT19: Nov | BX19: Dec | CB19: Total Makeup of Monthly Orders | CC19: Total Average Order Value
B20: Month | C20: 2019 | D20: 2020 | E20: Grand Total | L20: Month | M20: 2019 | N20: 2020 | O20: Grand Total | R20: Average | S20: =Q11 -> 790606.49 | T20: =R11 -> 792095.82 | V20: Row Labels | W20: 2019 | X20: 2020 | Y20: Grand Total | AA20: Month | AB20: 2019 | AC20: 2020 | AD20: Grand Total | AF20: Makeup of Monthly Orders | AH20: Average Order Value | AJ20: Makeup of Monthly Orders | AL20: Average Order Value | AN20: Makeup of Monthly Orders | AP20: Average Order Value | AR20: Makeup of Monthly Orders | AT20: Average Order Value | AV20: Makeup of Monthly Orders | AX20: Average Order Value | AZ20: Makeup of Monthly Orders | BB20: Average Order Value | BD20: Makeup of Monthly Orders | BF20: Average Order Value | BH20: Makeup of Monthly Orders | BJ20: Average Order Value | BL20: Makeup of Monthly Orders | BN20: Average Order Value | BP20: Makeup of Monthly Orders | BR20: Average Order Value | BT20: Makeup of Monthly Orders | BV20: Average Order Value | BX20: Makeup of Monthly Orders | BZ20: Average Order Value
B21: Jan | C21: 4516614.8 | D21: 5215699.8 | E21: 9732314.7 | L21: Jan | M21: 102650.34 | N21: 102268.62 | O21: 102445.42 | R21: Above Average | S21: =Q11+Q12 -> 1115919.2 | T21: =R11+R12 -> 999602.36 | V21: Jan | W21: 724231.31 | X21: 924639.02 | Y21: 1648870.3 | AA21: Jan | AB21: 44 | AC21: 51 | AD21: 95 | AE21: Category | AF21: 2019 | AG21: 2020 | AH21: 2019 | AI21: 2020 | AJ21: 2019 | AK21: 2020 | AL21: 2019 | AM21: 2020 | AN21: 2019 | AO21: 2020 | AP21: 2019 | AQ21: 2020 | AR21: 2019 | AS21: 2020 | AT21: 2019 | AU21: 2020 | AV21: 2019 | AW21: 2020 | AX21: 2019 | AY21: 2020 | AZ21: 2019 | BA21: 2020 | BB21: 2019 | BC21: 2020 | BD21: 2019 | BE21: 2020 | BF21: 2019 | BG21: 2020 | BH21: 2019 | BI21: 2020 | BJ21: 2019 | BK21: 2020 | BL21: 2019 | BM21: 2020 | BN21: 2019 | BO21: 2020 | BP21: 2019 | BQ21: 2020 | BR21: 2019 | BS21: 2020 | BT21: 2019 | BU21: 2020 | BV21: 2019 | BW21: 2020 | BX21: 2019 | BY21: 2020 | BZ21: 2019 | CA21: 2020
B22: Feb | C22: 2895563.9 | D22: 1959413 | E22: 4854976.9 | L22: Feb | M22: 65808.27 | N22: 69979.036 | O22: 67430.235 | V22: Feb | W22: 493204.9 | X22: 315750.51 | Y22: 808955.41 | AA22: Feb | AB22: 44 | AC22: 28 | AD22: 72 | AE22: Accessories | AF22: 1 | AG22: 1 | AH22: 36747.24 | AI22: 107716.72 | AJ22: 1 | AL22: 60592.4 | AN22: 1 | AO22: 1 | AP22: 76543.36 | AQ22: 46311.34 | AR22: 2 | AS22: 1 | AT22: 82860.585 | AU22: 178465.4 | AW22: 1 | AY22: 121736.23 | AZ22: 3 | BA22: 1 | BB22: 183687.76 | BC22: 122035.93 | BD22: 3 | BE22: 3 | BF22: 211061.69 | BG22: 163701.1 | BI22: 5 | BK22: 144243.13 | BL22: 1 | BM22: 2 | BN22: 94925 | BO22: 167759.02 | BP22: 1 | BQ22: 3 | BR22: 62947.82 | BS22: 104771.91 | BT22: 1 | BU22: 1 | BV22: 102771.44 | BW22: 32695.37 | BX22: 2 | BZ22: 224160.12 | CB22: 35 | CC22: 134398.02
B23: Mar | C23: 2521828 | D23: 3579943.8 | E23: 6101771.8 | L23: Mar | M23: 61508 | N23: 68845.074 | O23: 65610.45 | V23: Mar | W23: 429420.62 | X23: 596343.77 | Y23: 1025764.4 | AA23: Mar | AB23: 41 | AC23: 52 | AD23: 93 | AE23: Appliances | AF23: 6 | AG23: 6 | AH23: 117021.59 | AI23: 100486.17 | AJ23: 3 | AK23: 5 | AL23: 85879.317 | AM23: 91053.23 | AN23: 4 | AO23: 8 | AP23: 57945.445 | AQ23: 66500.464 | AR23: 6 | AS23: 7 | AT23: 137186.63 | AU23: 77208.951 | AV23: 3 | AW23: 9 | AX23: 135488.12 | AY23: 121417.55 | AZ23: 6 | BA23: 7 | BB23: 159086.14 | BC23: 196754.84 | BD23: 3 | BE23: 6 | BF23: 111631.72 | BG23: 139828.24 | BH23: 3 | BI23: 5 | BJ23: 70026.167 | BK23: 99976.53 | BL23: 10 | BM23: 3 | BN23: 106811.08 | BO23: 108435.87 | BP23: 3 | BQ23: 7 | BR23: 95949.58 | BS23: 93236.027 | BT23: 8 | BU23: 1 | BV23: 62464.864 | BW23: 149938.36 | BX23: 7 | BY23: 5 | BZ23: 190897.68 | CA23: 191928.22 | CB23: 131 | CC23: 115569.99
B24: Apr | C24: 4172236.8 | D24: 4069097.8 | E24: 8241334.5 | L24: Apr | M24: 115895.47 | N24: 107081.52 | O24: 111369.39 | V24: Apr | W24: 692753.62 | X24: 696219.46 | Y24: 1388973.1 | AA24: Apr | AB24: 36 | AC24: 38 | AD24: 74 | AE24: Beauty | AF24: 4 | AG24: 6 | AH24: 91790.695 | AI24: 94858.863 | AJ24: 6 | AK24: 3 | AL24: 65861.493 | AM24: 93563.487 | AN24: 4 | AO24: 3 | AP24: 65300.442 | AQ24: 71895.297 | AR24: 3 | AS24: 5 | AT24: 120516.26 | AU24: 141973.84 | AV24: 6 | AW24: 7 | AX24: 84972.35 | AY24: 75271.331 | AZ24: 4 | BA24: 6 | BB24: 150137.92 | BC24: 152779.16 | BD24: 9 | BE24: 3 | BF24: 169797.17 | BG24: 86745.057 | BH24: 7 | BI24: 4 | BJ24: 108305.81 | BK24: 66760.777 | BL24: 7 | BM24: 5 | BN24: 113780.85 | BO24: 103028.73 | BP24: 4 | BQ24: 3 | BR24: 119230.14 | BS24: 35161.397 | BT24: 4 | BU24: 5 | BV24: 124370.89 | BW24: 92074.64 | BX24: 3 | BY24: 4 | BZ24: 220625.51 | CA24: 131820.42 | CB24: 115 | CC24: 109296.21
B25: May | C25: 3825682 | D25: 5537943.8 | E25: 9363625.7 | L25: May | M25: 100675.84 | N25: 100689.89 | O25: 100684.15 | V25: May | W25: 648258.3 | X25: 914851.65 | Y25: 1563109.9 | AA25: May | AB25: 38 | AC25: 55 | AD25: 93 | AE25: Books | AF25: 1 | AG25: 5 | AH25: 173478.65 | AI25: 108100.68 | AJ25: 6 | AK25: 4 | AL25: 60870.328 | AM25: 65042.295 | AN25: 6 | AO25: 4 | AP25: 65617.933 | AQ25: 89002.577 | AR25: 3 | AS25: 5 | AT25: 98486.76 | AU25: 107973.15 | AV25: 1 | AW25: 5 | AX25: 49374.25 | AY25: 101677.3 | AZ25: 3 | BA25: 4 | BB25: 212801.78 | BC25: 192073.39 | BD25: 4 | BE25: 5 | BF25: 156870.69 | BG25: 147342.85 | BH25: 3 | BI25: 10 | BJ25: 144892.47 | BK25: 93513.124 | BL25: 3 | BM25: 9 | BN25: 101838.26 | BO25: 115130.78 | BP25: 6 | BQ25: 9 | BR25: 93440.65 | BS25: 74464.538 | BT25: 4 | BU25: 6 | BV25: 87393.643 | BW25: 110007.76 | BX25: 6 | BY25: 5 | BZ25: 203710.5 | CA25: 150539.13 | CB25: 117 | CC25: 112649.39
B26: Jun | C26: 7692234.9 | D26: 7158137.9 | E26: 14850373 | L26: Jun | M26: 163664.57 | N26: 166468.32 | O26: 165004.14 | V26: Jun | W26: 1305278.4 | X26: 1187044.5 | Y26: 2492322.8 | AA26: Jun | AB26: 47 | AC26: 43 | AD26: 90 | AE26: Clothing | AF26: 8 | AG26: 8 | AH26: 115469.15 | AI26: 97928.024 | AJ26: 4 | AK26: 4 | AL26: 75589.667 | AM26: 42820.183 | AN26: 9 | AO26: 8 | AP26: 65406.664 | AQ26: 63947.143 | AR26: 5 | AS26: 9 | AT26: 109646 | AU26: 110384.25 | AV26: 11 | AW26: 9 | AX26: 100904.85 | AY26: 84757.166 | AZ26: 6 | BA26: 1 | BB26: 150438.86 | BC26: 128221.13 | BD26: 11 | BE26: 5 | BF26: 171360.68 | BG26: 184148.12 | BH26: 1 | BI26: 5 | BJ26: 135211.42 | BK26: 106541.36 | BL26: 10 | BM26: 3 | BN26: 121062.81 | BO26: 106943.16 | BP26: 8 | BQ26: 5 | BR26: 81444.029 | BS26: 108892.92 | BT26: 4 | BU26: 8 | BV26: 102255.71 | BW26: 93380.943 | BX26: 8 | BY26: 5 | BZ26: 190958.52 | CA26: 210095.71 | CB26: 155 | CC26: 113946.34
B27: Jul | C27: 6638609.2 | D27: 5242556.5 | E27: 11881166 | L27: Jul | M27: 165965.23 | N27: 145626.57 | O27: 156331.13 | V27: Jul | W27: 1084227.4 | X27: 839989.39 | Y27: 1924216.8 | AA27: Jul | AB27: 40 | AC27: 36 | AD27: 76 | AE27: Electronics | AF27: 11 | AG27: 7 | AH27: 72315.763 | AI27: 84007.367 | AJ27: 7 | AK27: 4 | AL27: 60647.299 | AM27: 78687.152 | AN27: 4 | AO27: 10 | AP27: 61569.58 | AQ27: 65375.515 | AR27: 4 | AS27: 6 | AT27: 115434.62 | AU27: 97912.687 | AV27: 5 | AW27: 4 | AX27: 127419.89 | AY27: 136289.64 | AZ27: 7 | BA27: 8 | BB27: 141676.95 | BC27: 178279.6 | BD27: 3 | BE27: 5 | BF27: 145461.8 | BG27: 153067.07 | BH27: 1 | BI27: 4 | BJ27: 95966.17 | BK27: 78238.012 | BL27: 6 | BM27: 2 | BN27: 77519.912 | BO27: 123539.97 | BP27: 8 | BQ27: 5 | BR27: 119296.13 | BS27: 121334.24 | BT27: 5 | BU27: 7 | BV27: 78546.752 | BW27: 125092.66 | BX27: 7 | BY27: 4 | BZ27: 136763.78 | CA27: 175045.98 | CB27: 134 | CC27: 108075.21
B28: Aug | C28: 3437450.1 | D28: 4714525.2 | E28: 8151975.3 | L28: Aug | M28: 110885.49 | N28: 104767.23 | O28: 107262.83 | V28: Aug | W28: 580316.12 | X28: 768976.36 | Y28: 1349292.5 | AA28: Aug | AB28: 31 | AC28: 45 | AD28: 76 | AE28: Games | AF28: 6 | AG28: 9 | AH28: 121640.22 | AI28: 108595.65 | AJ28: 8 | AK28: 1 | AL28: 62735.369 | AM28: 61374.06 | AN28: 7 | AO28: 2 | AP28: 44769.331 | AQ28: 60683.66 | AR28: 10 | AS28: 3 | AT28: 118033.41 | AU28: 105187.08 | AV28: 3 | AW28: 13 | AX28: 62095.323 | AY28: 92771.99 | AZ28: 7 | BA28: 7 | BB28: 164179.56 | BC28: 131738.21 | BD28: 4 | BE28: 5 | BF28: 170397.46 | BG28: 188381.41 | BH28: 9 | BI28: 5 | BJ28: 129878.24 | BK28: 114048.95 | BL28: 6 | BM28: 5 | BN28: 71867.012 | BO28: 101369.37 | BP28: 6 | BQ28: 6 | BR28: 101941.6 | BS28: 102306.3 | BT28: 5 | BU28: 7 | BV28: 92824.324 | BW28: 108971.55 | BX28: 3 | BY28: 2 | BZ28: 235222.88 | CA28: 98998.45 | CB28: 139 | CC28: 110227.51
B29: Sep | C29: 4870060.5 | D29: 3778141.4 | E29: 8648201.9 | L29: Sep | M29: 99388.991 | N29: 111121.81 | O29: 104195.2 | V29: Sep | W29: 788191.58 | X29: 663167.65 | Y29: 1451359.2 | AA29: Sep | AB29: 49 | AC29: 34 | AD29: 83 | AE29: Other | AF29: 1 | AG29: 2 | AH29: 45256.74 | AI29: 119030.48 | AJ29: 1 | AK29: 1 | AL29: 24787.65 | AM29: 18897.97 | AO29: 4 | AQ29: 79785.75 | AV29: 2 | AW29: 3 | AX29: 50553.785 | AY29: 90071.207 | AZ29: 2 | BA29: 2 | BB29: 178267.98 | BC29: 179596.14 | BD29: 1 | BE29: 1 | BF29: 177802.7 | BG29: 45725.53 | BI29: 1 | BK29: 144530.35 | BL29: 2 | BM29: 1 | BN29: 55811.585 | BO29: 70657.26 | BQ29: 1 | BS29: 57333.85 | BU29: 2 | BW29: 123783.05 | BX29: 1 | BY29: 1 | BZ29: 383996.76 | CA29: 290551.74 | CB29: 29 | CC29: 112516.66
B30: Oct | C30: 4372149.5 | D30: 4869726.8 | E30: 9241876.4 | L30: Oct | M30: 101677.9 | N30: 97394.537 | O30: 99375.015 | V30: Oct | W30: 744434.48 | X30: 839700.96 | Y30: 1584135.4 | AA30: Oct | AB30: 43 | AC30: 50 | AD30: 93 | AE30: Outdoors | AF30: 1 | AG30: 3 | AH30: 103874.1 | AI30: 143616.59 | AJ30: 2 | AK30: 3 | AL30: 85145.885 | AM30: 61360.657 | AN30: 1 | AO30: 5 | AP30: 83141.47 | AQ30: 75357.568 | AS30: 1 | AU30: 152522.94 | AV30: 2 | AW30: 2 | AX30: 154369.25 | AY30: 118694.04 | AZ30: 2 | BA30: 4 | BB30: 110386.6 | BC30: 200705.4 | BD30: 1 | BE30: 1 | BF30: 77522.57 | BG30: 152676.77 | BH30: 3 | BI30: 1 | BJ30: 79821.24 | BK30: 87085.71 | BL30: 4 | BM30: 2 | BN30: 96617.792 | BO30: 117848.9 | BP30: 3 | BQ30: 2 | BR30: 117076.09 | BS30: 90997.21 | BU30: 3 | BW30: 70603.933 | BX30: 2 | BY30: 2 | BZ30: 180423.05 | CA30: 291502.93 | CB30: 50 | CC30: 118781.51
B31: Nov | C31: 2961318.6 | D31: 4734730.1 | E31: 7696048.7 | L31: Nov | M31: 89736.926 | N31: 105216.22 | O31: 98667.29 | V31: Nov | W31: 482287.62 | X31: 787670.37 | Y31: 1269958 | AA31: Nov | AB31: 33 | AC31: 45 | AD31: 78 | AE31: Smartphones | AF31: 5 | AG31: 4 | AH31: 127779.58 | AI31: 94415.525 | AJ31: 6 | AK31: 3 | AL31: 65515.082 | AM31: 70967.957 | AN31: 5 | AO31: 7 | AP31: 65425.678 | AQ31: 63900.306 | AR31: 3 | AS31: 1 | AT31: 112028.06 | AU31: 51416.24 | AV31: 5 | AW31: 2 | AX31: 103364.88 | AY31: 133276.58 | AZ31: 7 | BA31: 3 | BB31: 189537.14 | BC31: 111736.73 | BD31: 1 | BE31: 2 | BF31: 256603.66 | BG31: 44574.515 | BH31: 4 | BI31: 5 | BJ31: 98752.03 | BK31: 128746.58 | BM31: 2 | BO31: 92441.875 | BP31: 4 | BQ31: 9 | BR31: 103747.34 | BS31: 124754.67 | BT31: 2 | BU31: 5 | BV31: 122945.93 | BW31: 117360.34 | BX31: 5 | BY31: 5 | BZ31: 221901.28 | CA31: 164492.55 | CB31: 95 | CC31: 116859.52
B32: Dec | C32: 8713776 | D32: 5884298.3 | E32: 14598074 | L32: Dec | M32: 198040.36 | N32: 178312.07 | O32: 189585.38 | V32: Dec | W32: 1514673.6 | X32: 970796.22 | Y32: 2485469.8 | AA32: Dec | AB32: 44 | AC32: 33 | AD32: 77 | AE32: Grand Total | AF32: 44 | AG32: 51 | AH32: 102650.34 | AI32: 102268.62 | AJ32: 44 | AK32: 28 | AL32: 65808.27 | AM32: 69979.036 | AN32: 41 | AO32: 52 | AP32: 61508 | AQ32: 68845.074 | AR32: 36 | AS32: 38 | AT32: 115895.47 | AU32: 107081.52 | AV32: 38 | AW32: 55 | AX32: 100675.84 | AY32: 100689.89 | AZ32: 47 | BA32: 43 | BB32: 163664.57 | BC32: 166468.32 | BD32: 40 | BE32: 36 | BF32: 165965.23 | BG32: 145626.57 | BH32: 31 | BI32: 45 | BJ32: 110885.49 | BK32: 104767.23 | BL32: 49 | BM32: 34 | BN32: 99388.991 | BO32: 111121.81 | BP32: 43 | BQ32: 50 | BR32: 101677.9 | BS32: 97394.537 | BT32: 33 | BU32: 45 | BV32: 89736.926 | BW32: 105216.22 | BX32: 44 | BY32: 33 | BZ32: 198040.36 | CA32: 178312.07 | CB32: 1000 | CC32: 113361.74
B33: Grand Total | C33: 56617524 | D33: 56744214 | E33: 1.1336174e+08 | L33: Grand Total | M33: 115545.97 | N33: 111263.17 | O33: 113361.74 | V33: Grand Total | W33: 9487277.9 | X33: 9505149.8 | Y33: 18992428 | AA33: Grand Total | AB33: 490 | AC33: 510 | AD33: 1000
B36: Avg Profit per Sale | C36: Customer Analysis | G36: Difference in share of profits and sales | H36: Column Labels
B37: Customer | C37: 2019 | D37: 2020 | E37: Grand Total | G37: Row Labels | H37: 2019 | I37: 2020 | J37: Grand Total | P37: Profit Margin by Month | Q37: Column Labels
B38: Jan | C38: 16459.803 | D38: 18130.177 | E38: 17356.53 | G38: Jan | H38: -0.0058673652 | I38: -0.0023153856 | J38: -0.0081827508 | P38: Row Labels | Q38: 2019 | R38: 2020 | S38: Grand Total | AB38: Accessories
B39: Feb | C39: 11209.202 | D39: 11276.804 | E39: 11235.492 | G39: Feb | H39: -0.018031498 | I39: -0.011374926 | J39: -0.029406424 | P39: Jan | Q39: 0.16034826 | R39: 0.17727995 | S39: 0.16942222 | AB39: Appliances
B40: Mar | C40: 10473.674 | D40: 11468.149 | E40: 11029.725 | G40: Mar | H40: -0.018389904 | I40: -0.020600972 | J40: -0.038990876 | P40: Feb | Q40: 0.17033121 | R40: 0.16114546 | S40: 0.16662395 | AB40: Beauty
B41: Apr | C41: 19243.156 | D41: 18321.565 | E41: 18769.906 | G41: Apr | H41: 0.00047525373 | I41: -0.0013422609 | J41: -0.00086700718 | P41: Mar | Q41: 0.17028149 | R41: 0.16657909 | S41: 0.16810927 | AB41: Books
B42: May | C42: 17059.429 | D42: 16633.666 | E42: 16807.634 | G42: May | H42: -0.0038675389 | I42: -0.0068307157 | J42: -0.010698255 | P42: Apr | Q42: 0.1660389 | R42: 0.17109922 | S42: 0.1685374 | AB42: Clothing
...

Sheet MOMP
I1: More Orders = More Profit?
D2: This dashboard aims to look assess whether more orders drives profits or if there is something else in play. Orders placed between the start of 2019 and end of 2020 are included

